Workbook

Sheet Assumptions
A1: Complex LBO Model — Assumptions
A2: Yellow cells = hardcoded inputs. Change these to drive the whole model.
A4: Transaction
A5: Transaction / Entry Year | B5: 2026
A6: Hold Period (years) | B6: 5
A7: Entry EV / EBITDA Multiple | B7: 9
A8: Exit EV / EBITDA Multiple | B8: 9
A9: Transaction Fees (% of EV) | B9: 0.02
A10: Financing Fees (% of Total Debt) | B10: 0.02
A12: Operating Assumptions (Entry Year, Annual)
A13: Entry Revenue ($mm, annual) | B13: 500
A14: Revenue Growth Rate (annual) | B14: 0.06
A15: Entry EBITDA Margin | B15: 0.22
A16: EBITDA Margin Expansion (bps/yr) | B16: 0.0025
A17: D&A (% of Revenue) | B17: 0.035
A18: Capex (% of Revenue) | B18: 0.03
A19: Change in NWC (% of Rev. Growth $) | B19: 0.15
A20: Tax Rate | B20: 0.25
A21: Quarterly Revenue Growth Rate (derived) | B21: =(1+B14)^(1/4)-1
A22: Quarterly Margin Expansion (derived) | B22: =B16/4
A24: Base Rate & Cash Management
A25: SOFR (Base Rate) | B25: 0.045
A26: Minimum Cash Balance ($mm) | B26: 10
A27: Excess Cash Flow Sweep % | B27: 0.75
A29: Term Loan A (Amortizing, Senior Secured)
A30: TLA Leverage (x EBITDA) | B30: 2.5
A31: TLA Spread (over SOFR) | B31: 0.0325
A32: TLA Mandatory Amort. (%/yr of orig.) | B32: 0.075
A34: Term Loan B (Bullet, Institutional)
A35: TLB Leverage (x EBITDA) | B35: 2
A36: TLB Spread (over SOFR) | B36: 0.0425
A37: TLB Mandatory Amort. (%/yr of orig.) | B37: 0.01
A39: Revolving Credit Facility (RCF)
A40: Revolver Commitment ($mm) | B40: 75
A41: Revolver Spread (over SOFR) | B41: 0.03
A42: Revolver Commitment Fee (%/yr, undrawn) | B42: 0.005
A44: Mezzanine / PIK Notes
A45: Mezzanine Leverage (x EBITDA) | B45: 1
A46: Mezzanine Cash-Pay Rate | B46: 0.08
A47: Mezzanine PIK Rate | B47: 0.045
...

Sheet Sources & Uses
A1: Sources & Uses
A3: Entry EBITDA ($mm) | B3: ='Assumptions'!$B$13*'Assumptions'!$B$15
A5: Uses
A6: Purchase Enterprise Value | B6: =B3*'Assumptions'!$B$7
A7: Transaction Fees | B7: =B6*'Assumptions'!$B$9
A8: Financing Fees | B8: =B16*'Assumptions'!$B$10
A9: Total Uses | B9: =SUM(B6:B8)
A11: Sources
A12: Term Loan A | B12: =B3*'Assumptions'!$B$30
A13: Term Loan B | B13: =B3*'Assumptions'!$B$35
A14: Mezzanine / PIK Notes | B14: =B3*'Assumptions'!$B$45
A15: Revolver Draw at Close | B15: 0
A16: Total Debt | B16: =SUM(B12:B15)
A17: Management Rollover Equity | B17: =(B9-B16)*'Assumptions'!$B$55
A18: Sponsor Equity (plug) | B18: =B9-B16-B17
A19: Total Sources | B19: =B16+B17+B18
A20: Check (Sources - Uses) | B20: =B19-B9
A22: Revolver Commitment ($mm, undrawn facility size) | B22: ='Assumptions'!$B$40
A23: Opening Senior Secured Leverage (TLA+TLB / EBITDA) | B23: =(B12+B13)/B3
A24: Opening Total Leverage (incl. Mezz / EBITDA) | B24: =B16/B3

Sheet Operating Model
A1: Operating Model
A3: Period | B3: Close | C3: Y1Q1 | D3: Y1Q2 | E3: Y1Q3 | F3: Y1Q4 | G3: Y2Q1 | H3: Y2Q2 | I3: Y2Q3 | J3: Y2Q4 | K3: Y3Q1 | L3: Y3Q2 | M3: Y3Q3 | N3: Y3Q4 | O3: Y4Q1 | P3: Y4Q2 | Q3: Y4Q3 | R3: Y4Q4 | S3: Y5Q1 | T3: Y5Q2 | U3: Y5Q3 | V3: Y5Q4
A4: Year | B4: 0 | C4: 1 | D4: 1 | E4: 1 | F4: 1 | G4: 2 | H4: 2 | I4: 2 | J4: 2 | K4: 3 | L4: 3 | M4: 3 | N4: 3 | O4: 4 | P4: 4 | Q4: 4 | R4: 4 | S4: 5 | T4: 5 | U4: 5 | V4: 5
A5: Revenue | B5: ='Assumptions'!$B$13/4 | C5: =B5*(1+'Assumptions'!$B$21) | D5: =C5*(1+'Assumptions'!$B$21) | E5: =D5*(1+'Assumptions'!$B$21) | F5: =E5*(1+'Assumptions'!$B$21) | G5: =F5*(1+'Assumptions'!$B$21) | H5: =G5*(1+'Assumptions'!$B$21) | I5: =H5*(1+'Assumptions'!$B$21) | J5: =I5*(1+'Assumptions'!$B$21) | ... V5: =U5*(1+'Assumptions'!$B$21)
A6: % growth (QoQ) | C6: =C5/B5-1 | D6: =D5/C5-1 | E6: =E5/D5-1 | F6: =F5/E5-1 | G6: =G5/F5-1 | H6: =H5/G5-1 | I6: =I5/H5-1 | J6: =J5/I5-1 | ... V6: =V5/U5-1
A7: EBITDA Margin | B7: ='Assumptions'!$B$15 | C7: =B7+'Assumptions'!$B$22 | D7: =C7+'Assumptions'!$B$22 | E7: =D7+'Assumptions'!$B$22 | F7: =E7+'Assumptions'!$B$22 | G7: =F7+'Assumptions'!$B$22 | H7: =G7+'Assumptions'!$B$22 | I7: =H7+'Assumptions'!$B$22 | J7: =I7+'Assumptions'!$B$22 | ... V7: =U7+'Assumptions'!$B$22
A8: EBITDA | B8: =B5*B7 | C8: =C5*C7 | D8: =D5*D7 | E8: =E5*E7 | F8: =F5*F7 | G8: =G5*G7 | H8: =H5*H7 | I8: =I5*I7 | ... V8: =V5*V7
A9: Less: D&A | B9: =-B5*'Assumptions'!$B$17 | C9: =-C5*'Assumptions'!$B$17 | D9: =-D5*'Assumptions'!$B$17 | E9: =-E5*'Assumptions'!$B$17 | F9: =-F5*'Assumptions'!$B$17 | G9: =-G5*'Assumptions'!$B$17 | H9: =-H5*'Assumptions'!$B$17 | I9: =-I5*'Assumptions'!$B$17 | ... V9: =-V5*'Assumptions'!$B$17
A10: EBIT | B10: =B8+B9 | C10: =C8+C9 | D10: =D8+D9 | E10: =E8+E9 | F10: =F8+F9 | G10: =G8+G9 | H10: =H8+H9 | I10: =I8+I9 | ... V10: =V8+V9
A11: Less: Interest Expense, net (incl. PIK) | B11: 0 | C11: =-'Debt Schedule'!C16 | D11: =-'Debt Schedule'!D16 | E11: =-'Debt Schedule'!E16 | F11: =-'Debt Schedule'!F16 | G11: =-'Debt Schedule'!G16 | H11: =-'Debt Schedule'!H16 | I11: =-'Debt Schedule'!I16 | J11: =-'Debt Schedule'!J16 | ... V11: =-'Debt Schedule'!V16
A12: EBT | B12: =B10+B11 | C12: =C10+C11 | D12: =D10+D11 | E12: =E10+E11 | F12: =F10+F11 | G12: =G10+G11 | H12: =H10+H11 | I12: =I10+I11 | ... V12: =V10+V11
A13: Less: Cash Taxes | B13: =-MAX(B12,0)*'Assumptions'!$B$20 | C13: =-MAX(C12,0)*'Assumptions'!$B$20 | D13: =-MAX(D12,0)*'Assumptions'!$B$20 | E13: =-MAX(E12,0)*'Assumptions'!$B$20 | F13: =-MAX(F12,0)*'Assumptions'!$B$20 | G13: =-MAX(G12,0)*'Assumptions'!$B$20 | H13: =-MAX(H12,0)*'Assumptions'!$B$20 | I13: =-MAX(I12,0)*'Assumptions'!$B$20 | ... V13: =-MAX(V12,0)*'Assumptions'!$B$20
A14: Net Income | B14: =B12+B13 | C14: =C12+C13 | D14: =D12+D13 | E14: =E12+E13 | F14: =F12+F13 | G14: =G12+G13 | H14: =H12+H13 | I14: =I12+I13 | ... V14: =V12+V13

Sheet Free Cash Flow
A1: Free Cash Flow
A3: Period | B3: ='Operating Model'!B3 | C3: ='Operating Model'!C3 | D3: ='Operating Model'!D3 | E3: ='Operating Model'!E3 | F3: ='Operating Model'!F3 | G3: ='Operating Model'!G3 | H3: ='Operating Model'!H3 | I3: ='Operating Model'!I3 | ... V3: ='Operating Model'!V3
A4: Year | B4: ='Operating Model'!B4 | C4: ='Operating Model'!C4 | D4: ='Operating Model'!D4 | E4: ='Operating Model'!E4 | F4: ='Operating Model'!F4 | G4: ='Operating Model'!G4 | H4: ='Operating Model'!H4 | I4: ='Operating Model'!I4 | ... V4: ='Operating Model'!V4
A6: Net Income | B6: 0 | C6: ='Operating Model'!C14 | D6: ='Operating Model'!D14 | E6: ='Operating Model'!E14 | F6: ='Operating Model'!F14 | G6: ='Operating Model'!G14 | H6: ='Operating Model'!H14 | I6: ='Operating Model'!I14 | J6: ='Operating Model'!J14 | ... V6: ='Operating Model'!V14
A7: Plus: D&A | B7: 0 | C7: =-'Operating Model'!C9 | D7: =-'Operating Model'!D9 | E7: =-'Operating Model'!E9 | F7: =-'Operating Model'!F9 | G7: =-'Operating Model'!G9 | H7: =-'Operating Model'!H9 | I7: =-'Operating Model'!I9 | J7: =-'Operating Model'!J9 | ... V7: =-'Operating Model'!V9
A8: Less: Capex | B8: 0 | C8: =-'Operating Model'!C5*'Assumptions'!$B$18 | D8: =-'Operating Model'!D5*'Assumptions'!$B$18 | E8: =-'Operating Model'!E5*'Assumptions'!$B$18 | F8: =-'Operating Model'!F5*'Assumptions'!$B$18 | G8: =-'Operating Model'!G5*'Assumptions'!$B$18 | H8: =-'Operating Model'!H5*'Assumptions'!$B$18 | I8: =-'Operating Model'!I5*'Assumptions'!$B$18 | J8: =-'Operating Model'!J5*'Assumptions'!$B$18 | ... V8: =-'Operating Model'!V5*'Assumptions'!$B$18
A9: Less: Increase in NWC | B9: 0 | C9: =-('Operating Model'!C5-'Operating Model'!B5)*'Assumptions'!$B$19 | D9: =-('Operating Model'!D5-'Operating Model'!C5)*'Assumptions'!$B$19 | E9: =-('Operating Model'!E5-'Operating Model'!D5)*'Assumptions'!$B$19 | F9: =-('Operating Model'!F5-'Operating Model'!E5)*'Assumptions'!$B$19 | G9: =-('Operating Model'!G5-'Operating Model'!F5)*'Assumptions'!$B$19 | H9: =-('Operating Model'!H5-'Operating Model'!G5)*'Assumptions'!$B$19 | I9: =-('Operating Model'!I5-'Operating Model'!H5)*'Assumptions'!$B$19 | J9: =-('Operating Model'!J5-'Operating Model'!I5)*'Assumptions'!$B$19 | ... V9: =-('Operating Model'!V5-'Operating Model'!U5)*'Assumptions'!$B$19
A10: Plus: PIK Interest Add-back (non-cash) | B10: 0 | C10: ='Debt Schedule'!C14 | D10: ='Debt Schedule'!D14 | E10: ='Debt Schedule'!E14 | F10: ='Debt Schedule'!F14 | G10: ='Debt Schedule'!G14 | H10: ='Debt Schedule'!H14 | I10: ='Debt Schedule'!I14 | J10: ='Debt Schedule'!J14 | ... V10: ='Debt Schedule'!V14
A11: CFADS (Cash Flow Available for Debt Service) | B11: =B6+B7+B8+B9+B10 | C11: =C6+C7+C8+C9+C10 | D11: =D6+D7+D8+D9+D10 | E11: =E6+E7+E8+E9+E10 | F11: =F6+F7+F8+F9+F10 | G11: =G6+G7+G8+G9+G10 | H11: =H6+H7+H8+H9+H10 | I11: =I6+I7+I8+I9+I10 | ... V11: =V6+V7+V8+V9+V10

Sheet Debt Schedule
A1: Debt Schedule
A3: Period | B3: ='Operating Model'!B3 | C3: ='Operating Model'!C3 | D3: ='Operating Model'!D3 | E3: ='Operating Model'!E3 | F3: ='Operating Model'!F3 | G3: ='Operating Model'!G3 | H3: ='Operating Model'!H3 | I3: ='Operating Model'!I3 | ... V3: ='Operating Model'!V3
A4: Year | B4: ='Operating Model'!B4 | C4: ='Operating Model'!C4 | D4: ='Operating Model'!D4 | E4: ='Operating Model'!E4 | F4: ='Operating Model'!F4 | G4: ='Operating Model'!G4 | H4: ='Operating Model'!H4 | I4: ='Operating Model'!I4 | ... V4: ='Operating Model'!V4
A6: CFADS (from FCF tab, net of P&L interest via Net Income) | B6: 0 | C6: ='Free Cash Flow'!C11 | D6: ='Free Cash Flow'!D11 | E6: ='Free Cash Flow'!E11 | F6: ='Free Cash Flow'!F11 | G6: ='Free Cash Flow'!G11 | H6: ='Free Cash Flow'!H11 | I6: ='Free Cash Flow'!I11 | J6: ='Free Cash Flow'!J11 | ... V6: ='Free Cash Flow'!V11
A8: Interest & Fees (on Beginning Balances)
A9: Revolver Interest | B9: 0 | C9: =B51*('Assumptions'!$B$25+'Assumptions'!$B$41)/4 | D9: =C51*('Assumptions'!$B$25+'Assumptions'!$B$41)/4 | E9: =D51*('Assumptions'!$B$25+'Assumptions'!$B$41)/4 | F9: =E51*('Assumptions'!$B$25+'Assumptions'!$B$41)/4 | G9: =F51*('Assumptions'!$B$25+'Assumptions'!$B$41)/4 | H9: =G51*('Assumptions'!$B$25+'Assumptions'!$B$41)/4 | I9: =H51*('Assumptions'!$B$25+'Assumptions'!$B$41)/4 | J9: =I51*('Assumptions'!$B$25+'Assumptions'!$B$41)/4 | ... V9: =U51*('Assumptions'!$B$25+'Assumptions'!$B$41)/4
A10: Revolver Commitment Fee (on undrawn) | B10: 0 | C10: =('Assumptions'!$B$40-B51)*'Assumptions'!$B$42/4 | D10: =('Assumptions'!$B$40-C51)*'Assumptions'!$B$42/4 | E10: =('Assumptions'!$B$40-D51)*'Assumptions'!$B$42/4 | F10: =('Assumptions'!$B$40-E51)*'Assumptions'!$B$42/4 | G10: =('Assumptions'!$B$40-F51)*'Assumptions'!$B$42/4 | H10: =('Assumptions'!$B$40-G51)*'Assumptions'!$B$42/4 | I10: =('Assumptions'!$B$40-H51)*'Assumptions'!$B$42/4 | J10: =('Assumptions'!$B$40-I51)*'Assumptions'!$B$42/4 | ... V10: =('Assumptions'!$B$40-U51)*'Assumptions'!$B$42/4
A11: Term Loan A Interest | B11: 0 | C11: =B35*('Assumptions'!$B$25+'Assumptions'!$B$31)/4 | D11: =C35*('Assumptions'!$B$25+'Assumptions'!$B$31)/4 | E11: =D35*('Assumptions'!$B$25+'Assumptions'!$B$31)/4 | F11: =E35*('Assumptions'!$B$25+'Assumptions'!$B$31)/4 | G11: =F35*('Assumptions'!$B$25+'Assumptions'!$B$31)/4 | H11: =G35*('Assumptions'!$B$25+'Assumptions'!$B$31)/4 | I11: =H35*('Assumptions'!$B$25+'Assumptions'!$B$31)/4 | J11: =I35*('Assumptions'!$B$25+'Assumptions'!$B$31)/4 | ... V11: =U35*('Assumptions'!$B$25+'Assumptions'!$B$31)/4
A12: Term Loan B Interest | B12: 0 | C12: =B41*('Assumptions'!$B$25+'Assumptions'!$B$36)/4 | D12: =C41*('Assumptions'!$B$25+'Assumptions'!$B$36)/4 | E12: =D41*('Assumptions'!$B$25+'Assumptions'!$B$36)/4 | F12: =E41*('Assumptions'!$B$25+'Assumptions'!$B$36)/4 | G12: =F41*('Assumptions'!$B$25+'Assumptions'!$B$36)/4 | H12: =G41*('Assumptions'!$B$25+'Assumptions'!$B$36)/4 | I12: =H41*('Assumptions'!$B$25+'Assumptions'!$B$36)/4 | J12: =I41*('Assumptions'!$B$25+'Assumptions'!$B$36)/4 | ... V12: =U41*('Assumptions'!$B$25+'Assumptions'!$B$36)/4
A13: Mezzanine Cash-Pay Interest | B13: 0 | C13: =B46*'Assumptions'!$B$46/4 | D13: =C46*'Assumptions'!$B$46/4 | E13: =D46*'Assumptions'!$B$46/4 | F13: =E46*'Assumptions'!$B$46/4 | G13: =F46*'Assumptions'!$B$46/4 | H13: =G46*'Assumptions'!$B$46/4 | I13: =H46*'Assumptions'!$B$46/4 | J13: =I46*'Assumptions'!$B$46/4 | ... V13: =U46*'Assumptions'!$B$46/4
A14: Mezzanine PIK Interest (memo, non-cash) | B14: 0 | C14: =B46*'Assumptions'!$B$47/4 | D14: =C46*'Assumptions'!$B$47/4 | E14: =D46*'Assumptions'!$B$47/4 | F14: =E46*'Assumptions'!$B$47/4 | G14: =F46*'Assumptions'!$B$47/4 | H14: =G46*'Assumptions'!$B$47/4 | I14: =H46*'Assumptions'!$B$47/4 | J14: =I46*'Assumptions'!$B$47/4 | ... V14: =U46*'Assumptions'!$B$47/4
A15: Total Cash Interest & Fees | B15: 0 | C15: =C9+C10+C11+C12+C13 | D15: =D9+D10+D11+D12+D13 | E15: =E9+E10+E11+E12+E13 | F15: =F9+F10+F11+F12+F13 | G15: =G9+G10+G11+G12+G13 | H15: =H9+H10+H11+H12+H13 | I15: =I9+I10+I11+I12+I13 | J15: =J9+J10+J11+J12+J13 | ... V15: =V9+V10+V11+V12+V13
A16: Total P&L Interest Expense (incl. PIK) | B16: 0 | C16: =C15+C14 | D16: =D15+D14 | E16: =E15+E14 | F16: =F15+F14 | G16: =G15+G14 | H16: =H15+H14 | I16: =I15+I14 | J16: =J15+J14 | ... V16: =V15+V14
A18: Mandatory Amortization
A19: Term Loan A Mandatory Amort. | B19: 0 | C19: =-MIN('Sources & Uses'!$B$12*'Assumptions'!$B$32/4,B35) | D19: =-MIN('Sources & Uses'!$B$12*'Assumptions'!$B$32/4,C35) | E19: =-MIN('Sources & Uses'!$B$12*'Assumptions'!$B$32/4,D35) | F19: =-MIN('Sources & Uses'!$B$12*'Assumptions'!$B$32/4,E35) | G19: =-MIN('Sources & Uses'!$B$12*'Assumptions'!$B$32/4,F35) | H19: =-MIN('Sources & Uses'!$B$12*'Assumptions'!$B$32/4,G35) | I19: =-MIN('Sources & Uses'!$B$12*'Assumptions'!$B$32/4,H35) | J19: =-MIN('Sources & Uses'!$B$12*'Assumptions'!$B$32/4,I35) | ... V19: =-MIN('Sources & Uses'!$B$12*'Assumptions'!$B$32/4,U35)
A20: Term Loan B Mandatory Amort. | B20: 0 | C20: =-MIN('Sources & Uses'!$B$13*'Assumptions'!$B$37/4,B41) | D20: =-MIN('Sources & Uses'!$B$13*'Assumptions'!$B$37/4,C41) | E20: =-MIN('Sources & Uses'!$B$13*'Assumptions'!$B$37/4,D41) | F20: =-MIN('Sources & Uses'!$B$13*'Assumptions'!$B$37/4,E41) | G20: =-MIN('Sources & Uses'!$B$13*'Assumptions'!$B$37/4,F41) | H20: =-MIN('Sources & Uses'!$B$13*'Assumptions'!$B$37/4,G41) | I20: =-MIN('Sources & Uses'!$B$13*'Assumptions'!$B$37/4,H41) | J20: =-MIN('Sources & Uses'!$B$13*'Assumptions'!$B$37/4,I41) | ... V20: =-MIN('Sources & Uses'!$B$13*'Assumptions'!$B$37/4,U41)
A21: Total Mandatory Amortization | B21: 0 | C21: =C19+C20 | D21: =D19+D20 | E21: =E19+E20 | F21: =F19+F20 | G21: =G19+G20 | H21: =H19+H20 | I21: =I19+I20 | J21: =J19+J20 | ... V21: =V19+V20
A23: Cash Flow Before Revolver | B23: 0 | C23: =C6+C21 | D23: =D6+D21 | E23: =E6+E21 | F23: =F6+F21 | G23: =G6+G21 | H23: =H6+H21 | I23: =I6+I21 | J23: =J6+J21 | ... V23: =V6+V21
A25: Revolver Sweep / Draw (1st priority)
A26: Revolver Draw / (Paydown) | B26: 0 | C26: =IF(C23<0,-C23,-MIN(C23,B51)) | D26: =IF(D23<0,-D23,-MIN(D23,C51)) | E26: =IF(E23<0,-E23,-MIN(E23,D51)) | F26: =IF(F23<0,-F23,-MIN(F23,E51)) | G26: =IF(G23<0,-G23,-MIN(G23,F51)) | H26: =IF(H23<0,-H23,-MIN(H23,G51)) | I26: =IF(I23<0,-I23,-MIN(I23,H51)) | J26: =IF(J23<0,-J23,-MIN(J23,I51)) | ... V26: =IF(V23<0,-V23,-MIN(V23,U51))
A27: Cash Flow After Revolver | B27: 0 | C27: =C23+C26 | D27: =D23+D26 | E27: =E23+E26 | F27: =F23+F26 | G27: =G23+G26 | H27: =H23+H26 | I27: =I23+I26 | J27: =J23+J26 | ... V27: =V23+V26
A29: Cash Flow Available for ECF Sweep | B29: 0 | C29: =MAX(C27,0)*'Assumptions'!$B$27 | D29: =MAX(D27,0)*'Assumptions'!$B$27 | E29: =MAX(E27,0)*'Assumptions'!$B$27 | F29: =MAX(F27,0)*'Assumptions'!$B$27 | G29: =MAX(G27,0)*'Assumptions'!$B$27 | H29: =MAX(H27,0)*'Assumptions'!$B$27 | I29: =MAX(I27,0)*'Assumptions'!$B$27 | J29: =MAX(J27,0)*'Assumptions'!$B$27 | ... V29: =MAX(V27,0)*'Assumptions'!$B$27
A31: Term Loan A
A32: Beginning Balance | B32: 0 | C32: =B35 | D32: =C35 | E32: =D35 | F32: =E35 | G32: =F35 | H32: =G35 | I32: =H35 | J32: =I35 | ... V32: =U35
A33: Mandatory Amortization | B33: 0 | C33: =C19 | D33: =D19 | E33: =E19 | F33: =F19 | G33: =G19 | H33: =H19 | I33: =I19 | J33: =J19 | ... V33: =V19
A34: Optional (ECF) Sweep | B34: 0 | C34: =-MIN(MAX(C29,0),C32+C33) | D34: =-MIN(MAX(D29,0),D32+D33) | E34: =-MIN(MAX(E29,0),E32+E33) | F34: =-MIN(MAX(F29,0),F32+F33) | G34: =-MIN(MAX(G29,0),G32+G33) | H34: =-MIN(MAX(H29,0),H32+H33) | I34: =-MIN(MAX(I29,0),I32+I33) | J34: =-MIN(MAX(J29,0),J32+J33) | ... V34: =-MIN(MAX(V29,0),V32+V33)
A35: Ending Balance | B35: ='Sources & Uses'!$B$12 | C35: =C32+C33+C34 | D35: =D32+D33+D34 | E35: =E32+E33+E34 | F35: =F32+F33+F34 | G35: =G32+G33+G34 | H35: =H32+H33+H34 | I35: =I32+I33+I34 | J35: =J32+J33+J34 | ... V35: =V32+V33+V34
A37: Term Loan B
A38: Beginning Balance | B38: 0 | C38: =B41 | D38: =C41 | E38: =D41 | F38: =E41 | G38: =F41 | H38: =G41 | I38: =H41 | J38: =I41 | ... V38: =U41
A39: Mandatory Amortization | B39: 0 | C39: =C20 | D39: =D20 | E39: =E20 | F39: =F20 | G39: =G20 | H39: =H20 | I39: =I20 | J39: =J20 | ... V39: =V20
A40: Optional (ECF) Sweep (after TLA repaid) | B40: 0 | C40: =-MIN(MAX(C29+C34,0),C38+C39) | D40: =-MIN(MAX(D29+D34,0),D38+D39) | E40: =-MIN(MAX(E29+E34,0),E38+E39) | F40: =-MIN(MAX(F29+F34,0),F38+F39) | G40: =-MIN(MAX(G29+G34,0),G38+G39) | H40: =-MIN(MAX(H29+H34,0),H38+H39) | I40: =-MIN(MAX(I29+I34,0),I38+I39) | J40: =-MIN(MAX(J29+J34,0),J38+J39) | ... V40: =-MIN(MAX(V29+V34,0),V38+V39)
A41: Ending Balance | B41: ='Sources & Uses'!$B$13 | C41: =C38+C39+C40 | D41: =D38+D39+D40 | E41: =E38+E39+E40 | F41: =F38+F39+F40 | G41: =G38+G39+G40 | H41: =H38+H39+H40 | I41: =I38+I39+I40 | J41: =J38+J39+J40 | ... V41: =V38+V39+V40
A43: Mezzanine / PIK Notes (not swept; repaid at exit)
A44: Beginning Balance | B44: 0 | C44: =B46 | D44: =C46 | E44: =D46 | F44: =E46 | G44: =F46 | H44: =G46 | I44: =H46 | J44: =I46 | ... V44: =U46
A45: PIK Accrual (+) | B45: 0 | C45: =C14 | D45: =D14 | E45: =E14 | F45: =F14 | G45: =G14 | H45: =H14 | I45: =I14 | J45: =J14 | ... V45: =V14
A46: Ending Balance | B46: ='Sources & Uses'!$B$14 | C46: =C44+C45 | D46: =D44+D45 | E46: =E44+E45 | F46: =F44+F45 | G46: =G44+G45 | H46: =H44+H45 | I46: =I44+I45 | J46: =J44+J45 | ... V46: =V44+V45
A48: Revolving Credit Facility (RCF)
A49: Beginning Balance | B49: 0 | C49: =B51 | D49: =C51 | E49: =D51 | F49: =E51 | G49: =F51 | H49: =G51 | I49: =H51 | J49: =I51 | ... V49: =U51
A50: Draw / (Paydown) | B50: ='Sources & Uses'!$B$15 | C50: =C26 | D50: =D26 | E50: =E26 | F50: =F26 | G50: =G26 | H50: =H26 | I50: =I26 | J50: =J26 | ... V50: =V26
A51: Ending Balance | B51: =MAX(B49+B50,0) | C51: =MAX(C49+C50,0) | D51: =MAX(D49+D50,0) | E51: =MAX(E49+E50,0) | F51: =MAX(F49+F50,0) | G51: =MAX(G49+G50,0) | H51: =MAX(H49+H50,0) | I51: =MAX(I49+I50,0) | ... V51: =MAX(V49+V50,0)
...

Sheet Returns
A1: Returns Analysis
A3: Exit Period | B3: ='Operating Model'!V3
A4: Exit LTM EBITDA | B4: ='Debt Schedule'!V58
A5: Exit EV/EBITDA Multiple | B5: ='Assumptions'!$B$8
A6: Exit Enterprise Value | B6: =B4*'Assumptions'!$B$8
A7: Less: Net Debt at Exit | B7: =-'Debt Schedule'!V55
A8: Exit Equity Value (Total) | B8: =B6+B7
A10: Invested Capital at Close
A11: Sponsor Equity | B11: ='Sources & Uses'!$B$18
A12: Management Rollover Equity | B12: ='Sources & Uses'!$B$17
A13: Total Invested Equity | B13: =B11+B12
A15: Tiered Promote Waterfall
A16: Total MOIC (on combined capital) | B16: =B8/B13
A17: Tier 1 Proceeds (up to Tier 1 MOIC) | B17: =MIN(B8,'Assumptions'!$B$56*B13)
A18: Tier 2 Proceeds (Tier 1 to Tier 2 MOIC) | B18: =MAX(0,MIN(B8,'Assumptions'!$B$58*B13)-'Assumptions'!$B$56*B13)
A19: Tier 3 Proceeds (above Tier 2 MOIC) | B19: =MAX(0,B8-'Assumptions'!$B$58*B13)
A20: Management Proceeds | B20: =B17*'Assumptions'!$B$57+B18*'Assumptions'!$B$59+B19*'Assumptions'!$B$60
A21: Sponsor Proceeds | B21: =B8-B20
A23: Sponsor Returns
A24: Hold Period (years) | B24: ='Assumptions'!$B$6
A25: Sponsor MOIC | B25: =B21/B11
A26: Sponsor IRR | B26: =(B25)^(1/B24)-1
A28: Management Returns
A29: Management MOIC | B29: =IFERROR(B20/B12,0)
A30: Management IRR | B30: =IFERROR((B29)^(1/B24)-1,0)
A32: Note: exit assumed at end of 20 quarters (col V). Management's share of proceeds ratchets up by tier as total MOIC crosses the Tier 1 / Tier 2 thresholds on the Assumptions tab. Change FORECAST_YEARS in the script for a different hold length.
